Workbook

Sheet 00_읽는법
A1: 이 표 읽는 법 (실무진 안내)
A3: 컬럼 | B3: 뜻 | C3: 값 설명
A4: 우선순위 | B4: 언제 만드나 | C4: P0=런칭에 꼭 필요 · P1=런칭 직후 · P2=나중에
A5: 담당 | B5: 누가 만드나 | C5: PM=기획·정책·계약 · 인쇄개발=상품·가격·옵션 · 쇼핑개발=쇼핑몰화면·주문·페이지빌더 · 협업=두 팀 함께
A6: 개발규모 | B6: 작업량 가늠 | C6: S=작음 · M=보통 · L=큼 · XL=매우 큼
A7: 진행상태 | B7: 지금 상태 | C7: 진행중 · 대기(외부계약·결정 기다림) · 미착수 · 완료
A8: Phase | B8: 단계 | C8: Phase 1=런칭 · 2=안정화 · 3=확장
A9: 확인·결정 필요사항 | B9: 먼저 풀어야 할 것 | C9: 계약·정책 결정·데이터 정리 등 시작 전 챙길 선행조건 (쉬운 말로 기재)
A10: 비고 | B10: 적용 상품 | C10: 해당 기능이 어떤 상품에 들어가는지
A12: ※ 개발자용 기술 상세(레드프린팅 SDK 함수, 스키마 구조 등)는 별도 파일 ‘후니프린팅 인쇄상품 IA 상세’를 참고하세요.

Sheet 01_역할정의
A1: 후니프린팅 통합 IA — 역할 분담 & 진행현황 (인쇄상품 상세 반영)
A2: 3인 체제 · PM(1)/인쇄개발(1)/쇼핑개발(1) · 기준 IA 144개 기능 (인쇄상품 상세 35행 포함)
A4: 역할 | B4: 트랙 | C4: 핵심 책임범위 | D4: 담당 IA 영역 | E4: 현재 진행상황 | F4: 주요 산출물
A5: PM | B5: 기획·조율 | C5: 일정/우선순위, 운영정책 확정, 외부계약(알림톡·PG·이니시스·에디터), QA, 실무진 테스트 조율, 콘텐츠(약관·인쇄가이드) | D5: 전 영역 의사결정·정책·계약·검수 | E5: 운영정책 5건 + 에디터 도입(D3/D4) 결정 대기 | F5: 일정표·정책 확정서·계약 완료·QA
A6: 인쇄개발 | B6: 상품·가격·위젯 | C6: 관리자 상품관리(상품·사이즈·소재·용지·가격) + 고객 인쇄상품 옵션위젯·실시간가격(3엔진)·가이드·견적, CPQ 엔진 | D6: 관리자 상품관리 14종 + 인쇄상품 옵션/가격/가이드 24종 | E6: ▶ 진행중: 상품·가격 DB 스키마 완료→데이터 매핑·시뮬레이터 검수 / 가격엔진(C1) | F6: 검증된 상품·가격 DB·CPQ 3엔진·임베드형 옵션·가격 위젯
A7: 쇼핑개발 | B7: 페이지빌더·쇼핑 | C7: 상세페이지 빌더, 파일업로드·주문전환·플로팅·장바구니, 쇼핑몰 사용자 전반, 관리자 커머스 운영 | D7: 쇼핑몰 사용자 + 인쇄상품 파일/주문 11종 + 관리자 커머스 33종 | E7: ▶ 진행중: 상세 콘텐츠 빌더(G1) 작업→실무진 테스트 전달 | F7: 상세페이지 빌더·스토어프론트·주문/결제 플로우·관리자 운영툴
A9: ⟡ 협업 포인트
A10: · 인쇄상품 옵션·가격 위젯(인쇄개발) ↔ 상세페이지 임베드·주문전환(쇼핑개발) — Aurora Web Components 위에 결합
A11: · 온라인 에디터 D3·D4 — 협업/외부 도입 검토, 런칭 후순위(P2)
A12: · B15 옵션 제약 ↔ 폴리모픽 스키마(ref_key+ref_dim_cd) — 데이터로 표현돼야 동적 위젯 성립

Sheet 02_IA마스터
A1: No | B1: 시스템 | C1: 영역 | D1: 기능 | E1: 우선순위 | F1: 담당 | G1: 개발규모 | H1: 진행상태 | I1: Phase | J1: 확인·결정 필요사항 (선행조건) | K1: 비고
A2: 1 | B2: 쇼핑몰 | C2: 로그인 | D2: 일반 로그인 | E2: P0 | F2: 쇼핑개발 | G2: S | H2: 미착수 | I2: Phase 1 (런칭)
A3: 2 | B3: 쇼핑몰 | C3: 로그인 | D3: 아이디 찾기 (이메일 발송) | E3: P0 | F3: 쇼핑개발 | G3: S | H3: 미착수 | I3: Phase 1 (런칭)
A4: 3 | B4: 쇼핑몰 | C4: 로그인 | D4: 비밀번호 찾기 (휴대폰 임시PW) | E4: P1 | F4: 쇼핑개발 | G4: M | H4: 대기 | I4: Phase 2 (안정화) | J4: 알림톡 서비스 계약 먼저 (PM) | K4: 알림톡 서비스 계약 필요
A5: 4 | B5: 쇼핑몰 | C5: 회원가입 | D5: 약관동의 | E5: P0 | F5: 쇼핑개발 | G5: S | H5: 미착수 | I5: Phase 1 (런칭)
A6: 5 | B6: 쇼핑몰 | C6: 회원가입 | D6: 정보입력 | E6: P0 | F6: 쇼핑개발 | G6: M | H6: 미착수 | I6: Phase 1 (런칭)
A7: 6 | B7: 쇼핑몰 | C7: 회원가입 | D7: 이메일 중복확인 | E7: P0 | F7: 쇼핑개발 | G7: S | H7: 미착수 | I7: Phase 1 (런칭)
A8: 7 | B8: 쇼핑몰 | C8: 회원가입 | D8: 휴대전화 인증 | E8: P1 | F8: 쇼핑개발 | G8: M | H8: 대기 | I8: Phase 2 (안정화) | J8: 휴대폰 인증·문자 서비스 계약 먼저 (PM) | K8: 이슈사항에 추가
A9: 8 | B9: 쇼핑몰 | C9: 회원가입 | D9: 가입완료 메일 발송 | E9: P0 | F9: 쇼핑개발 | G9: S | H9: 미착수 | I9: Phase 1 (런칭)
A10: 9 | B10: 쇼핑몰 | C10: 마이페이지 | D10: 주문조회 | E10: P0 | F10: 쇼핑개발 | G10: M | H10: 미착수 | I10: Phase 1 (런칭)
A11: 10 | B11: 쇼핑몰 | C11: 마이페이지 | D11: 주문상세조회(편집상품 미리보기) | E11: P0 | F11: 쇼핑개발 | G11: L | H11: 미착수 | I11: Phase 1 (런칭)
A12: 11 | B12: 쇼핑몰 | C12: 마이페이지 | D12: 옵션보관함 (저장된 인쇄옵션) | E12: P1 | F12: 쇼핑개발 | G12: M | H12: 미착수 | I12: Phase 2 (안정화) | K12: 재주문시 옵션 불러오기
A13: 12 | B13: 쇼핑몰 | C13: 마이페이지 | D13: 쿠폰관리 | E13: P1 | F13: 쇼핑개발 | G13: S | H13: 미착수 | I13: Phase 2 (안정화)
A14: 13 | B14: 쇼핑몰 | C14: 마이페이지 | D14: 쿠폰등록 | E14: P1 | F14: 쇼핑개발 | G14: S | H14: 미착수 | I14: Phase 2 (안정화) | K14: 로그인한 상태에서만 등록가능/등록후 결과
A15: 14 | B15: 쇼핑몰 | C15: 마이페이지 | D15: 프린팅머니 | E15: P1 | F15: 쇼핑개발 | G15: M | H15: 대기 | I15: Phase 2 (안정화) | J15: 결제대행(PG) 연동 먼저 (PM) | K15: PG 연동 필요
A16: 15 | B16: 쇼핑몰 | C16: 마이페이지 | D16: 머니충전 | E16: P1 | F16: 쇼핑개발 | G16: M | H16: 대기 | I16: Phase 2 (안정화) | J16: 결제대행(PG) 연동 먼저 (PM) | K16: 결제가 가능해야함
A17: 16 | B17: 쇼핑몰 | C17: 마이페이지 | D17: 나의 상품Q&A + 문의하기 | E17: P1 | F17: 쇼핑개발 | G17: M | H17: 미착수 | I17: Phase 2 (안정화)
A18: 17 | B18: 쇼핑몰 | C18: 마이페이지 | D18: 나의 리뷰 | E18: P2 | F18: 쇼핑개발 | G18: M | H18: 미착수 | I18: Phase 3 (확장) | K18: 배송완료건에 한해 리뷰쓰면 즉시노출 / 쿠폰자동발행으로 쿠폰지급
A19: 18 | B19: 쇼핑몰 | C19: 마이페이지 | D19: 리뷰쓰기(사진업로드) 수정/삭제 | E19: P2 | F19: 쇼핑개발 | G19: M | H19: 미착수 | I19: Phase 3 (확장) | K19: 삭제시에도 쿠폰자동회수
A20: 19 | B20: 쇼핑몰 | C20: 마이페이지 | D20: 나의 체험단 활동내역 + 후기 | E20: P2 | F20: 쇼핑개발 | G20: M | H20: 미착수 | I20: Phase 3 (확장) | K20: 당첨자만 후기등록 활성화
A21: 20 | B21: 쇼핑몰 | C21: 마이페이지 | D21: 1:1문의 + 문의하기 | E21: P1 | F21: 쇼핑개발 | G21: M | H21: 미착수 | I21: Phase 2 (안정화)
A22: 21 | B22: 쇼핑몰 | C22: 마이페이지 | D22: 회원정보수정 | E22: P0 | F22: 쇼핑개발 | G22: M | H22: 미착수 | I22: Phase 1 (런칭)
A23: 22 | B23: 쇼핑몰 | C23: 마이페이지 | D23: 회원정보수정_비밀번호입력 | E23: P0 | F23: 쇼핑개발 | G23: S | H23: 미착수 | I23: Phase 1 (런칭) | K23: 정보수정전 비밀번호 입력후 페이지전환
A24: 23 | B24: 쇼핑몰 | C24: 마이페이지 | D24: 비밀번호변경 | E24: P0 | F24: 쇼핑개발 | G24: S | H24: 미착수 | I24: Phase 1 (런칭) | J24: 비밀번호 변경 시 본인확인 방법 결정 필요 (PM) | K24: 변경전 인증방법은?
A25: 24 | B25: 쇼핑몰 | C25: 마이페이지 | D25: 회원탈퇴 | E25: P0 | F25: 쇼핑개발 | G25: S | H25: 미착수 | I25: Phase 1 (런칭) | J25: 회원탈퇴 시 본인확인 방법 결정 필요 (PM) | K25: 탈퇴전 인증방법은?
A26: 25 | B26: 쇼핑몰 | C26: 마이페이지 | D26: 증빙서류발급내역 (현금영수증+세금계산서) | E26: P1 | F26: 쇼핑개발 | G26: M | H26: 미착수 | I26: Phase 2 (안정화) | J26: 증빙서류 발급 규칙 결정 필요 (PM) | K26: 신청가능/완료/불가/신용카드 4상태 / 발행내역 / 신청완료시 발급상태 / 미발행건 발급가능?
A27: 26 | B27: 쇼핑몰 | C27: 마이페이지 | D27: 사업자정보(목록) | E27: P1 | F27: 쇼핑개발 | G27: S | H27: 미착수 | I27: Phase 2 (안정화)
A28: 27 | B28: 쇼핑몰 | C28: 마이페이지 | D28: 사업자정보등록(쓰기) | E28: P1 | F28: 쇼핑개발 | G28: M | H28: 미착수 | I28: Phase 2 (안정화)
A29: 28 | B29: 쇼핑몰 | C29: 마이페이지 | D29: 현금영수증정보 | E29: P1 | F29: 쇼핑개발 | G29: M | H29: 미착수 | I29: Phase 2 (안정화) | J29: 현금영수증 정보 수집 여부 결정 필요 (PM) | K29: 필요여부 확인해야함
A30: 29 | B30: 쇼핑몰 | C30: 마이페이지 | D30: 메인 | E30: P0 | F30: 쇼핑개발 | G30: S | H30: 미착수 | I30: Phase 1 (런칭)
A31: 30 | B31: 쇼핑몰 | C31: 마이페이지 | D31: 서브메인(랜딩페이지) | E31: P2 | F31: 쇼핑개발 | G31: M | H31: 미착수 | I31: Phase 3 (확장) | K31: 1depth 의 페이지 (랜딩페이지로 사용) - 프로모션이미지 등록가능하게
A32: 31 | B32: 쇼핑몰 | C32: 마이페이지 | D32: LIST (검색결과) | E32: P0 | F32: 쇼핑개발 | G32: M | H32: 미착수 | I32: Phase 1 (런칭) | K32: 2depth 의 리스트페이지 (랜딩페이지로 사용)
A33: 32 | B33: 쇼핑몰 | C33: 인쇄상품 | D33: A1 상품 기본정보 세팅(상품코드·주문가능·회원) | E33: P0 | F33: 쇼핑개발 | G33: S | H33: 미착수 | I33: Phase 1 (런칭) | K33: 적용 상품: 전체
A34: 33 | B34: 쇼핑몰 | C34: 인쇄상품 | D34: A2 상품별 옵션 목록 불러오기 | E34: P0 | F34: 인쇄개발 | G34: L | H34: 진행중 | I34: Phase 1 (런칭) | J34: 상품 종류마다 옵션 구성이 달라 상품별 옵션목록을 제공해야 함 | K34: 적용 상품: 전체
A35: 34 | B35: 쇼핑몰 | C35: 인쇄상품 | D35: B1 규격(사이즈) 선택 | E35: P0 | F35: 인쇄개발 | G35: M | H35: 미착수 | I35: Phase 1 (런칭) | K35: 적용 상품: 전체
A36: 35 | B36: 쇼핑몰 | C36: 인쇄상품 | D36: B2 비규격 사용자입력(가로×세로 최소/최대) | E36: P0 | F36: 인쇄개발 | G36: M | H36: 미착수 | I36: Phase 1 (런칭) | J36: 가로×세로 직접입력 시 면적으로 가격 계산 | K36: 적용 상품: 실사·아크릴
A37: 36 | B37: 쇼핑몰 | C37: 인쇄상품 | D37: B3 수량 선택+직접입력 | E37: P0 | F37: 인쇄개발 | G37: M | H37: 미착수 | I37: Phase 1 (런칭) | K37: 적용 상품: 전체
A38: 37 | B38: 쇼핑몰 | C38: 인쇄상품 | D38: B4 종이/소재 선택(+평량) | E38: P0 | F38: 인쇄개발 | G38: M | H38: 미착수 | I38: Phase 1 (런칭) | K38: 적용 상품: 전체
A39: 38 | B39: 쇼핑몰 | C39: 인쇄상품 | D39: B5 인쇄 도수(단/양면)+별색·화이트 | E39: P0 | F39: 인쇄개발 | G39: M | H39: 미착수 | I39: Phase 1 (런칭) | K39: 적용 상품: 디지털·스티커·책자·캘린더
A40: 39 | B40: 쇼핑몰 | C40: 인쇄상품 | D40: B6 코팅 | E40: P1 | F40: 인쇄개발 | G40: S | H40: 미착수 | I40: Phase 2 (안정화) | K40: 적용 상품: 디지털·스티커·책자·실사
...

Sheet 03_페이즈일정
A1: 페이즈별 진행 계획 (인쇄상품 상세 반영)
A3: Phase | B3: 목표 | C3: 인쇄개발 범위 | D3: 쇼핑개발 범위 | E3: PM 선행/조율
A4: Phase 0 (현재) | B4: 진행 기반작업 마무리 | C4: 상품·가격 DB 매핑+시뮬레이터 검수 / 가격엔진(C1)·옵션API(A2) | D4: 상세 콘텐츠 빌더(G1) 완성→실무진 테스트 | E4: 정책 5건 + 에디터 도입 결정 / 계약 협상
A5: Phase 1 (런칭·P0) | B5: 매출 백본 (57건) | C5: 옵션위젯(규격·수량·종이·인쇄·제본 B1~B10)·실시간가격(C1)·작업사이즈(E4)·관리자 상품/가격 셋업 | D5: 파일업로드(D1)·미리보기(D2)·주문전환(F1~F4)·상세빌더(G1)·스토어프론트·회원·결제·관리자 주문관리 | E5: 이니시스 계약, 인증/배송비 정책, 약관·가이드 콘텐츠
A6: Phase 2 (안정화·P1) | B6: 운영·재구매·B2B (64건) | C6: 코팅·커팅·박/형압·캘린더가공(B6~B13)·가격표/견적(C2·C3)·가이드(E1~E3)·굿즈/포장 등록 | D6: 쿠폰·머니·증빙·고객센터·옵션보관함(F5)·거래처/원장·통계·후불·알림톡 | E6: 알림톡·PG 계약, 증빙 정책, 대량견적 IA 보완
A7: Phase 3 (확장·P2) | B7: 성장·미결정 의존 (23건) | C7: 수작/디자인 등록·개별포장(B14) | D7: 온라인 에디터(D3·D4)·리뷰·체험단·마케팅·고급통계 | E7: 에디터 도입·수작 존치 결정·마케팅 기획

Sheet 04_진행현황
A1: ① 담당 × 우선순위 (건수)
A3: 담당 \ 우선순위 | B3: P0 | C3: P1 | D3: P2 | E3: 합계
A4: PM | B4: =COUNTIFS('02_IA마스터'!$F$2:$F$145,$A4,'02_IA마스터'!$E$2:$E$145,B$3) -> 0 | C4: =COUNTIFS('02_IA마스터'!$F$2:$F$145,$A4,'02_IA마스터'!$E$2:$E$145,C$3) -> 0 | D4: =COUNTIFS('02_IA마스터'!$F$2:$F$145,$A4,'02_IA마스터'!$E$2:$E$145,D$3) -> 0 | E4: =SUM(B4:D4) -> 0
A5: 인쇄개발 | B5: =COUNTIFS('02_IA마스터'!$F$2:$F$145,$A5,'02_IA마스터'!$E$2:$E$145,B$3) -> 20 | C5: =COUNTIFS('02_IA마스터'!$F$2:$F$145,$A5,'02_IA마스터'!$E$2:$E$145,C$3) -> 15 | D5: =COUNTIFS('02_IA마스터'!$F$2:$F$145,$A5,'02_IA마스터'!$E$2:$E$145,D$3) -> 3 | E5: =SUM(B5:D5) -> 38
A6: 쇼핑개발 | B6: =COUNTIFS('02_IA마스터'!$F$2:$F$145,$A6,'02_IA마스터'!$E$2:$E$145,B$3) -> 37 | C6: =COUNTIFS('02_IA마스터'!$F$2:$F$145,$A6,'02_IA마스터'!$E$2:$E$145,C$3) -> 49 | D6: =COUNTIFS('02_IA마스터'!$F$2:$F$145,$A6,'02_IA마스터'!$E$2:$E$145,D$3) -> 18 | E6: =SUM(B6:D6) -> 104
A7: 협업 | B7: =COUNTIFS('02_IA마스터'!$F$2:$F$145,$A7,'02_IA마스터'!$E$2:$E$145,B$3) -> 0 | C7: =COUNTIFS('02_IA마스터'!$F$2:$F$145,$A7,'02_IA마스터'!$E$2:$E$145,C$3) -> 0 | D7: =COUNTIFS('02_IA마스터'!$F$2:$F$145,$A7,'02_IA마스터'!$E$2:$E$145,D$3) -> 2 | E7: =SUM(B7:D7) -> 2
A8: 합계 | B8: =SUM(B4:B7) -> 57 | C8: =SUM(C4:C7) -> 64 | D8: =SUM(D4:D7) -> 23 | E8: =SUM(E4:E7) -> 144
A10: ② 진행상태 분포
A12: 완료 | B12: 진행중 | C12: 대기 | D12: 미착수
A13: =COUNTIF('02_IA마스터'!$H$2:$H$145,"완료") -> 0 | B13: =COUNTIF('02_IA마스터'!$H$2:$H$145,"진행중") -> 9 | C13: =COUNTIF('02_IA마스터'!$H$2:$H$145,"대기") -> 9 | D13: =COUNTIF('02_IA마스터'!$H$2:$H$145,"미착수") -> 126
A15: ③ 담당별 가중 공수 (S=1·M=2·L=4·XL=8)
A17: 담당 | B17: 공수점수 | C17: P0 공수점수
A18: PM | B18: =COUNTIFS('02_IA마스터'!$F$2:$F$145,$A18,'02_IA마스터'!$G$2:$G$145,"S")+COUNTIFS('02_IA마스터'!$F$2:$F$145,$A18,'02_IA마스터'!$G$2:$G$145,"M")*2+COUNTIFS('02_IA마스터'!$F$2:$F$145,$A18,'02_IA마스터'!$G$2:$G$145,"L")*4+COUNTIFS('02_IA마스터'!$F$2:$F$145,$A18,'02_IA마스터'!$G$2:$G$145,"XL")*8 -> 0 | C18: =COUNTIFS('02_IA마스터'!$F$2:$F$145,$A18,'02_IA마스터'!$G$2:$G$145,"S",'02_IA마스터'!$E$2:$E$145,"P0")+COUNTIFS('02_IA마스터'!$F$2:$F$145,$A18,'02_IA마스터'!$G$2:$G$145,"M",'02_IA마스터'!$E$2:$E$145,"P0")*2+COUNTIFS('02_IA마스터'!$F$2:$F$145,$A18,'02_IA마스터'!$G$2:$G$145,"L",'02_IA마스터'!$E$2:$E$145,"P0")*4+COUNTIFS('02_IA마스터'!$F$2:$F$145,$A18,'02_IA마스터'!$G$2:$G$145,"XL",'02_IA마스터'!$E$2:$E$145,"P0")*8 -> 0
A19: 인쇄개발 | B19: =COUNTIFS('02_IA마스터'!$F$2:$F$145,$A19,'02_IA마스터'!$G$2:$G$145,"S")+COUNTIFS('02_IA마스터'!$F$2:$F$145,$A19,'02_IA마스터'!$G$2:$G$145,"M")*2+COUNTIFS('02_IA마스터'!$F$2:$F$145,$A19,'02_IA마스터'!$G$2:$G$145,"L")*4+COUNTIFS('02_IA마스터'!$F$2:$F$145,$A19,'02_IA마스터'!$G$2:$G$145,"XL")*8 -> 92 | C19: =COUNTIFS('02_IA마스터'!$F$2:$F$145,$A19,'02_IA마스터'!$G$2:$G$145,"S",'02_IA마스터'!$E$2:$E$145,"P0")+COUNTIFS('02_IA마스터'!$F$2:$F$145,$A19,'02_IA마스터'!$G$2:$G$145,"M",'02_IA마스터'!$E$2:$E$145,"P0")*2+COUNTIFS('02_IA마스터'!$F$2:$F$145,$A19,'02_IA마스터'!$G$2:$G$145,"L",'02_IA마스터'!$E$2:$E$145,"P0")*4+COUNTIFS('02_IA마스터'!$F$2:$F$145,$A19,'02_IA마스터'!$G$2:$G$145,"XL",'02_IA마스터'!$E$2:$E$145,"P0")*8 -> 58
A20: 쇼핑개발 | B20: =COUNTIFS('02_IA마스터'!$F$2:$F$145,$A20,'02_IA마스터'!$G$2:$G$145,"S")+COUNTIFS('02_IA마스터'!$F$2:$F$145,$A20,'02_IA마스터'!$G$2:$G$145,"M")*2+COUNTIFS('02_IA마스터'!$F$2:$F$145,$A20,'02_IA마스터'!$G$2:$G$145,"L")*4+COUNTIFS('02_IA마스터'!$F$2:$F$145,$A20,'02_IA마스터'!$G$2:$G$145,"XL")*8 -> 201 | C20: =COUNTIFS('02_IA마스터'!$F$2:$F$145,$A20,'02_IA마스터'!$G$2:$G$145,"S",'02_IA마스터'!$E$2:$E$145,"P0")+COUNTIFS('02_IA마스터'!$F$2:$F$145,$A20,'02_IA마스터'!$G$2:$G$145,"M",'02_IA마스터'!$E$2:$E$145,"P0")*2+COUNTIFS('02_IA마스터'!$F$2:$F$145,$A20,'02_IA마스터'!$G$2:$G$145,"L",'02_IA마스터'!$E$2:$E$145,"P0")*4+COUNTIFS('02_IA마스터'!$F$2:$F$145,$A20,'02_IA마스터'!$G$2:$G$145,"XL",'02_IA마스터'!$E$2:$E$145,"P0")*8 -> 82
A21: 협업 | B21: =COUNTIFS('02_IA마스터'!$F$2:$F$145,$A21,'02_IA마스터'!$G$2:$G$145,"S")+COUNTIFS('02_IA마스터'!$F$2:$F$145,$A21,'02_IA마스터'!$G$2:$G$145,"M")*2+COUNTIFS('02_IA마스터'!$F$2:$F$145,$A21,'02_IA마스터'!$G$2:$G$145,"L")*4+COUNTIFS('02_IA마스터'!$F$2:$F$145,$A21,'02_IA마스터'!$G$2:$G$145,"XL")*8 -> 12 | C21: =COUNTIFS('02_IA마스터'!$F$2:$F$145,$A21,'02_IA마스터'!$G$2:$G$145,"S",'02_IA마스터'!$E$2:$E$145,"P0")+COUNTIFS('02_IA마스터'!$F$2:$F$145,$A21,'02_IA마스터'!$G$2:$G$145,"M",'02_IA마스터'!$E$2:$E$145,"P0")*2+COUNTIFS('02_IA마스터'!$F$2:$F$145,$A21,'02_IA마스터'!$G$2:$G$145,"L",'02_IA마스터'!$E$2:$E$145,"P0")*4+COUNTIFS('02_IA마스터'!$F$2:$F$145,$A21,'02_IA마스터'!$G$2:$G$145,"XL",'02_IA마스터'!$E$2:$E$145,"P0")*8 -> 0
A23: ※ 인쇄상품 상세 반영 후 인쇄개발 부하가 14건→38건으로 현실화. P0 공수에서 인쇄개발이 옵션위젯·가격엔진으로 크게 증가 — 쇼핑개발 단독 병목 우려가 완화됨. 단 D1·F2 등 쇼핑개발 P0도 여전히 높아 Shopby 빌트인 활용 권장.
